<?xml version="1.0" encoding="utf-8"?>
<!-- =================================================================================== -->
<!-- |    This document was autogenerated by xacro from mirobot_urdf_2.xacro           | -->
<!-- |    EDITING THIS FILE BY HAND IS NOT RECOMMENDED                                 | -->
<!-- =================================================================================== -->
<!-- This URDF was automatically created by SolidWorks to URDF Exporter! Originally created by Stephen Brawner (brawner@gmail.com) 
     Commit Version: 1.5.1-0-g916b5db  Build Version: 1.5.7152.31018
     For more information, please see http://wiki.ros.org/sw_urdf_exporter -->
<robot name="mirobot_urdf_2">
  <link name="base_link">
    <visual>
      <origin rpy="0 0 0" xyz="0 0 0"/>
      <geometry>
        <mesh filename="assets/urdf/mirobot_description/meshes/base_link.dae"/>
      </geometry>
      <material name="base_link_color">
        <color rgba="0.44 0.5 0.56 1"/>
      </material>
    </visual>
    <collision>
      <origin rpy="0 0 0" xyz="0 0 0"/>
      <geometry>
        <mesh filename="assets/urdf/mirobot_description/meshes/base_link.obj"/>
      </geometry>
    </collision>
  </link>
  <link name="Link1">
    <visual>
      <origin rpy="0 0 0" xyz="0 0 0"/>
      <geometry>
        <mesh filename="assets/urdf/mirobot_description/meshes/Link1.dae"/>
      </geometry>
      <material name="Link1_color">
        <color rgba="0.83 0.83 0.83 1"/>
      </material>
    </visual>
    <collision>
      <origin rpy="0 0 0" xyz="0 0 0"/>
      <geometry>
        <mesh filename="assets/urdf/mirobot_description/meshes/Link1.obj"/>
      </geometry>
    </collision>
  </link>
  <joint name="joint1" type="revolute">
    <origin rpy="0 0 0" xyz="0 0 0.065406"/>
    <parent link="base_link"/>
    <child link="Link1"/>
    <axis xyz="0 0 1"/>
    <limit effort="80" lower="-1.7453" upper="1.7453" velocity="1.1344"/>
  </joint>
  <link name="Link2">
    <visual>
      <origin rpy="0 0 0" xyz="0 0 0"/>
      <geometry>
        <mesh filename="assets/urdf/mirobot_description/meshes/Link2.dae"/>
      </geometry>
      <material name="Link2_color">
        <color rgba="1 0.65 0 1"/>
      </material>
    </visual>
    <collision>
      <origin rpy="0 0 0" xyz="0 0 0"/>
      <geometry>
        <mesh filename="assets/urdf/mirobot_description/meshes/Link2.obj"/>
      </geometry>
    </collision>
  </link>
  <joint name="joint2" type="revolute">
    <origin rpy="3.1402 -1.5708 1.5722" xyz="0.029687 -0.022 0.061593"/>
    <parent link="Link1"/>
    <child link="Link2"/>
    <axis xyz="0 0 1"/>
    <limit effort="50" lower="-1.0471" upper="1.5707" velocity="1.1344"/>
  </joint>
  <link name="Link3">
    <visual>
      <origin rpy="0 0 0" xyz="0 0 0"/>
      <geometry>
        <mesh filename="assets/urdf/mirobot_description/meshes/Link3.dae"/>
      </geometry>
      <material name="Link3_color">
        <color rgba="0.83 0.83 0.83 1"/>
      </material>
    </visual>
    <collision>
      <origin rpy="0 0 0" xyz="0 0 0"/>
      <geometry>
        <mesh filename="assets/urdf/mirobot_description/meshes/Link3.obj"/>
      </geometry>
    </collision>
  </link>
  <joint name="joint3" type="revolute">
    <origin rpy="0 0 0" xyz="0.108 0 -0.0094471"/>
    <parent link="Link2"/>
    <child link="Link3"/>
    <axis xyz="0 0 1"/>
    <limit effort="10" lower="-3.1415" upper="0.8726" velocity="0.4886"/>
  </joint>
  <link name="Link4">
    <visual>
      <origin rpy="0 0 0" xyz="0 0 0"/>
      <geometry>
        <mesh filename="assets/urdf/mirobot_description/meshes/Link4.dae"/>
      </geometry>
      <material name="Link4_color">
        <color rgba="1 0.65 0 1"/>
      </material>
    </visual>
    <collision>
      <origin rpy="0 0 0" xyz="0 0 0"/>
      <geometry>
        <mesh filename="assets/urdf/mirobot_description/meshes/Link4.obj"/>
      </geometry>
    </collision>
  </link>
  <joint name="joint4" type="revolute">
    <origin rpy="-1.5708 0 0" xyz="0.020001 0.10743 0.031439"/>
    <parent link="Link3"/>
    <child link="Link4"/>
    <axis xyz="0 0 1"/>
    <limit effort="10" lower="-3.1415" upper="3.1415" velocity="1.9198"/>
  </joint>

  <link name="Link5">
    <visual>
      <origin rpy="0 0 0" xyz="0 0 0"/>
      <geometry>
        <mesh filename="assets/urdf/mirobot_description/meshes/Link5_align.dae"/>
      </geometry>
    </visual>
    <collision>
      <!-- Following offset is required to avoid the problem that the joint doesn't move in IsaacGym. -->
      <!-- It seems a collision bug of isaacgym because this URDF model works well in ROS rviz. -->
      <origin rpy="0 0 0" xyz="-0.04 0 0"/>
      <geometry>
        <mesh filename="assets/urdf/mirobot_description/meshes/Link5_align.obj"/>
      </geometry>
    </collision>
  </link>
  <joint name="joint5" type="revolute">
    <!-- <origin rpy="1.5708 -1.5708 -3.1416" xyz="0 -0.010414 0.06155"/> -->
    <origin rpy="1.5708 -1.5708 -3.1416" xyz="0 0.0 0.06155"/>
    <parent link="Link4"/>
    <child link="Link5"/>
    <axis xyz="0 0 -1"/>
    <limit effort="10" lower="-3.14" upper="0.698" velocity="0.5759"/>
  </joint>

  <link name="Link6">
    <visual>
      <origin rpy="0 0 0" xyz="0 0 0"/>
      <geometry>
        <mesh filename="assets/urdf/mirobot_description/meshes/Link6.dae"/>
      </geometry>
      <material name="Link6_color">
        <color rgba="0.83 0.83 0.83 1"/>
      </material>
    </visual>
    <collision>
      <!-- Following offset is required to avoid the problem that the joint doesn't move in IsaacGym. -->
      <!-- It seems a collision bug of isaacgym because this URDF model works well in ROS rviz. -->
      <origin rpy="0 0 0" xyz="-0.04 0 0"/>
      <geometry>
        <mesh filename="assets/urdf/mirobot_description/meshes/Link6.obj"/>
      </geometry>
    </collision>
  </link>
  <joint name="joint6" type="revolute">
    <!-- <origin rpy="-1.5708 0 0" xyz="0 -0.01628 0.010525"/> -->
    <origin rpy="-1.5708 0 0" xyz="0 -0.01628 0"/>
    <parent link="Link5"/>
    <child link="Link6"/>
    <axis xyz="0 0 1"/>
    <limit effort="15" lower="-3.1415" upper="3.1415" velocity="1.1519"/>
  </joint>

  <link name="mirobot_hand">
    <visual>
      <geometry>
        <mesh filename="assets/urdf/mirobot_description/meshes/mirobot_hand.dae"/>
      </geometry>
    </visual>
    <collision>
      <geometry>
        <mesh filename="assets/urdf/mirobot_description/meshes/mirobot_hand.obj"/>
      </geometry>
    </collision>
  </link>
  <joint name="mirobot_hand_joint" type="fixed">
    <parent link="Link6"/>
    <child link="mirobot_hand"/>
    <origin rpy="3.1415 0 0" xyz="0 0 -0.008"/>
  </joint>

  <link name="left_finger">
    <visual>
      <geometry>
        <mesh filename="assets/urdf/mirobot_description/meshes/mirobot_leftfinger.dae"/>
      </geometry>
    </visual>
    <collision>
      <geometry>
        <mesh filename="assets/urdf/mirobot_description/meshes/mirobot_leftfinger.obj"/>
      </geometry>
    </collision>
  </link>
  <link name="right_finger">
    <visual>
      <geometry>
        <mesh filename="assets/urdf/mirobot_description/meshes/mirobot_rightfinger.dae"/>
      </geometry>
    </visual>
    <collision>
      <geometry>
        <mesh filename="assets/urdf/mirobot_description/meshes/mirobot_rightfinger.obj"/>
      </geometry>
    </collision>
  </link>
  <joint name="right_finger_joint" type="prismatic">
    <parent link="mirobot_hand"/>
    <child link="right_finger"/>
    <origin rpy="0 0 0" xyz="0.01 0 0.024"/>
    <axis xyz="0 1 0"/>
    <dynamics damping="10.0"/>
    <limit effort="20" lower="0.0" upper="0.0175" velocity="0.2"/>
  </joint>
  <joint name="left_finger_joint" type="prismatic">
    <parent link="mirobot_hand"/>
    <child link="left_finger"/>
    <origin rpy="0 0 0" xyz="0.01 0 0.024"/>
    <axis xyz="0 -1 0"/>
    <dynamics damping="10.0"/>
    <limit effort="20" lower="0.0" upper="0.0175" velocity="0.2"/>
    <mimic joint="left_finger_joint"/>
  </joint>
</robot>

