<?xml version="1.0" encoding="utf-8"?>
<!-- =================================================================================== -->
<!-- |    This document was autogenerated by xacro from mirobot_urdf_2.xacro           | -->
<!-- |    EDITING THIS FILE BY HAND IS NOT RECOMMENDED                                 | -->
<!-- =================================================================================== -->
<!-- This URDF was automatically created by SolidWorks to URDF Exporter! Originally created by Stephen Brawner (brawner@gmail.com) 
     Commit Version: 1.5.1-0-g916b5db  Build Version: 1.5.7152.31018
     For more information, please see http://wiki.ros.org/sw_urdf_exporter -->
<robot name="mirobot_urdf_2">
  <link name="base_link">
    <inertial>
      <origin rpy="0 0 0" xyz="0.00072554 2.2065E-05 0.024268"/>
      <mass value="0.01"/>
      <inertia ixx="10" ixy="0" ixz="0" iyy="10" iyz="0" izz="10"/>
    </inertial>
    <visual>
      <origin rpy="0 0 0" xyz="0 0 0"/>
      <geometry>
        <mesh filename="package://mirobot_description/meshes/base_link.obj"/>
      </geometry>
      <material name="">
        <color rgba="0.44 0.5 0.56 1"/>
      </material>
    </visual>
    <collision>
      <origin rpy="0 0 0" xyz="0 0 0"/>
      <geometry>
        <mesh filename="package://mirobot_description/meshes/base_link.obj"/>
      </geometry>
    </collision>
  </link>
  <link name="Link1">
    <inertial>
      <origin rpy="0 0 0" xyz="0.011601 0.022341 0.044136"/>
      <mass value="0.001"/>
      <inertia ixx="10" ixy="0" ixz="0" iyy="10" iyz="0" izz="10"/>
    </inertial>
    <visual>
      <origin rpy="0 0 0" xyz="0 0 0"/>
      <geometry>
        <mesh filename="package://mirobot_description/meshes/Link1.obj"/>
      </geometry>
      <material name="">
        <color rgba="0.83 0.83 0.83 1"/>
      </material>
    </visual>
    <collision>
      <origin rpy="0 0 0" xyz="0 0 0"/>
      <geometry>
        <mesh filename="package://mirobot_description/meshes/Link1.obj"/>
      </geometry>
    </collision>
  </link>
  <joint name="joint1" type="revolute">
    <origin rpy="0 0 0" xyz="0 0 0.065406"/>
    <parent link="base_link"/>
    <child link="Link1"/>
    <axis xyz="0 0 1"/>
    <limit effort="200" lower="-1.7453" upper="2.7925" velocity="200"/>
  </joint>
  <link name="Link2">
    <inertial>
      <origin rpy="0 0 0" xyz="0.054694 0.0036383 -0.0056108"/>
      <mass value="0.001"/>
      <inertia ixx="10" ixy="0" ixz="0" iyy="10" iyz="0" izz="10"/>
    </inertial>
    <visual>
      <origin rpy="0 0 0" xyz="0 0 0"/>
      <geometry>
        <mesh filename="package://mirobot_description/meshes/Link2.obj"/>
      </geometry>
      <material name="">
        <color rgba="1 0.65 0 1"/>
      </material>
    </visual>
    <collision>
      <origin rpy="0 0 0" xyz="0 0 0"/>
      <geometry>
        <mesh filename="package://mirobot_description/meshes/Link2.obj"/>
      </geometry>
    </collision>
  </link>
  <joint name="joint2" type="revolute">
    <origin rpy="3.1402 -1.5708 1.5722" xyz="0.029687 -0.022 0.061593"/>
    <parent link="Link1"/>
    <child link="Link2"/>
    <axis xyz="0 0 1"/>
    <limit effort="200" lower="-0.5235" upper="1.2217" velocity="200"/>
  </joint>
  <link name="Link3">
    <inertial>
      <origin rpy="0 0 0" xyz="0.0099997 0.0071403 0.037517"/>
      <mass value="0.001"/>
      <inertia ixx="10" ixy="0" ixz="0" iyy="10" iyz="0" izz="10"/>
    </inertial>
    <visual>
      <origin rpy="0 0 0" xyz="0 0 0"/>
      <geometry>
        <mesh filename="package://mirobot_description/meshes/Link3.obj"/>
      </geometry>
      <material name="">
        <color rgba="0.83 0.83 0.83 1"/>
      </material>
    </visual>
    <collision>
      <origin rpy="0 0 0" xyz="0 0 0"/>
      <geometry>
        <mesh filename="package://mirobot_description/meshes/Link3.obj"/>
      </geometry>
    </collision>
  </link>
  <joint name="joint3" type="revolute">
    <origin rpy="0 0 0" xyz="0.108 0 -0.0094471"/>
    <parent link="Link2"/>
    <child link="Link3"/>
    <axis xyz="0 0 1"/>
    <limit effort="200" lower="-2.9671" upper="1.0472" velocity="200"/>
  </joint>
  <link name="Link4">
    <inertial>
      <origin rpy="0 0 0" xyz="-8.0804E-06 0.0043797 0.040569"/>
      <mass value="0.001"/>
      <inertia ixx="10" ixy="0" ixz="0" iyy="10" iyz="0" izz="10"/>
    </inertial>
    <visual>
      <origin rpy="0 0 0" xyz="0 0 0"/>
      <geometry>
        <mesh filename="package://mirobot_description/meshes/Link4.obj"/>
      </geometry>
      <material name="">
        <color rgba="1 0.65 0 1"/>
      </material>
    </visual>
    <collision>
      <origin rpy="0 0 0" xyz="0 0 0"/>
      <geometry>
        <mesh filename="package://mirobot_description/meshes/Link4.obj"/>
      </geometry>
    </collision>
  </link>
  <joint name="joint4" type="revolute">
    <origin rpy="-1.5708 0 0" xyz="0.020001 0.10743 0.031439"/>
    <parent link="Link3"/>
    <child link="Link4"/>
    <axis xyz="0 0 1"/>
    <limit effort="200" lower="-6.1086" upper="6.1086" velocity="200"/>
  </joint>
  <link name="Link5">
    <inertial>
      <origin rpy="0 0 0" xyz="0.00025302 -0.0020133 0.010352"/>
      <mass value="0.001"/>
      <inertia ixx="10" ixy="0" ixz="0" iyy="10" iyz="0" izz="10"/>
    </inertial>
    <visual>
      <origin rpy="0 0 0" xyz="0 0 0"/>
      <geometry>
        <mesh filename="package://mirobot_description/meshes/Link5.obj"/>
      </geometry>
      <material name="">
        <color rgba="0.44 0.5 0.56 1"/>
      </material>
    </visual>
    <collision>
      <origin rpy="0 0 0" xyz="0 0 0"/>
      <geometry>
        <mesh filename="package://mirobot_description/meshes/Link5.obj"/>
      </geometry>
    </collision>
  </link>
  <joint name="joint5" type="revolute">
    <origin rpy="1.5708 -1.5708 -3.1416" xyz="0 -0.010414 0.06155"/>
    <parent link="Link4"/>
    <child link="Link5"/>
    <axis xyz="0 0 -1"/>
    <limit effort="200" lower="-3.5779" upper="0.6283" velocity="200"/>
  </joint>
  <link name="Link6">
    <inertial>
      <origin rpy="0 0 0" xyz="5.5511E-17 5.421E-20 -0.010506"/>
      <mass value="0.001"/>
      <inertia ixx="10" ixy="0" ixz="0" iyy="10" iyz="0" izz="10"/>
    </inertial>
    <visual>
      <origin rpy="0 0 0" xyz="0 0 0"/>
      <geometry>
        <mesh filename="package://mirobot_description/meshes/Link6.obj"/>
      </geometry>
      <material name="">
        <color rgba="0.83 0.83 0.83 1"/>
      </material>
    </visual>
    <collision>
      <origin rpy="0 0 0" xyz="0 0 0"/>
      <geometry>
        <mesh filename="package://mirobot_description/meshes/Link6.obj"/>
      </geometry>
    </collision>
  </link>
  <joint name="joint6" type="revolute">
    <origin rpy="-1.5708 0 0" xyz="0 -0.01628 0.010525"/>
    <parent link="Link5"/>
    <child link="Link6"/>
    <axis xyz="0 0 1"/>
    <limit effort="200" lower="-6.2832" upper="6.2832" velocity="200"/>
  </joint>
  <!-- from this, gripper -->
  <joint name="mirobot_hand_joint" type="fixed">
    <origin rpy="-1.5708 0 -1.5708" xyz="0 0 -0.005"/>
    <parent link="Link6"/>
    <child link="mirobot_hand"/>
    <axis xyz="0 0 1"/>
  </joint>
  <link name="mirobot_hand">
    <visual>
      <geometry>
        <mesh filename="package://mirobot_description/meshes/mirobot_hand.obj"/>
      </geometry>
      <color rgba="0.83 0.83 0.83 1"/>
    </visual>
    <collision>
      <geometry>
        <mesh filename="package://mirobot_description/meshes/mirobot_hand.obj"/>
      </geometry>
    </collision>
  </link>
  <link name="left_finger">
    <visual>
      <geometry>
        <mesh filename="package://mirobot_description/meshes/finger.obj"/>
      </geometry>
    </visual>
    <collision>
      <geometry>
        <mesh filename="package://mirobot_description/meshes/finger.obj"/>
      </geometry>
    </collision>
  </link>
  <link name="right_finger">
    <visual>
      <origin rpy="0 3.14159265359 0" xyz="0 0 0"/>
      <geometry>
        <mesh filename="package://mirobot_description/meshes/finger.obj"/>
      </geometry>
    </visual>
    <collision>
      <origin rpy="0 3.14159265359 0" xyz="0 0 0"/>
      <geometry>
        <mesh filename="package://mirobot_description/meshes/finger.obj"/>
      </geometry>
    </collision>
  </link>
  <joint name="left_finger_joint" type="prismatic">
    <parent link="mirobot_hand"/>
    <child link="left_finger"/>
    <origin rpy="0 0 0" xyz="-0.015 0 0"/>
    <axis xyz="1 0 0"/>
    <dynamics damping="10.0"/>
    <limit effort="20" lower="0.0" upper="0.015" velocity="0.2"/>
  </joint>
  <joint name="right_finger_joint" type="prismatic">
    <parent link="mirobot_hand"/>
    <child link="right_finger"/>
    <origin rpy="0 0 0" xyz="0.015 0 0"/>
    <axis xyz="-1 0 0"/>
    <dynamics damping="10.0"/>
    <limit effort="20" lower="0.0" upper="0.015" velocity="0.2"/>
    <mimic joint="left_finger_joint"/>
  </joint>
</robot>

